Workbook

Sheet 구매목록
A1: 회사 다과 구매 목록 (마켓컬리)
A2: 예산 | B2: 500000 | C2: 합계 | D2: =SUM(F5:F48) -> 498344 | E2: 잔액 | F2: =B2-D2 -> 1656
A4: 구분 | B4: 카테고리 | C4: 상품명 | D4: 단가(원) | E4: 수량 | F4: 금액(원) | G4: 할인율(%) | H4: 후기수 | I4: 링크 | J4: 메모
A5: 필수 | B5: 필수 | C5: [해태] 사브레 252g | D5: 3580 | E5: 15 | F5: =D5*E5 -> 53700 | G5: 0 | H5: 999 | I5: https://www.kurly.com/goods/1000198076
A6: 필수 | B6: 필수 | C6: [모리나가] 밀크, 소금 카라멜 2종 (택1) | D6: 3400 | E6: 15 | F6: =D6*E6 -> 51000 | G6: 0 | H6: 999 | I6: https://www.kurly.com/goods/1000490151
A7: 추천 | B7: 가성비 소포장 과자(브랜드 무관) | C7: [오리온] 비쵸비 125g | D7: 2860 | E7: 2 | F7: =D7*E7 -> 5720 | G7: 0 | H7: 9999 | I7: https://www.kurly.com/goods/1000154390
A8: 추천 | B8: 가성비 소포장 과자(브랜드 무관) | C8: [롯데] 칸쵸 4봉입 196g | D8: 4000 | E8: 2 | F8: =D8*E8 -> 8000 | G8: 0 | H8: 999 | I8: https://www.kurly.com/goods/5079339
A9: 추천 | B9: 가성비 소포장 과자(브랜드 무관) | C9: [청우] 그랑쉘 사과 195g (10입) | D9: 4280 | E9: 2 | F9: =D9*E9 -> 8560 | G9: 0 | H9: 999 | I9: https://www.kurly.com/goods/5061289
A10: 추천 | B10: 가성비 소포장 과자(브랜드 무관) | C10: [크라운] 빅파이 딸기 324g | D10: 3840 | E10: 2 | F10: =D10*E10 -> 7680 | G10: 0 | H10: 999 | I10: https://www.kurly.com/goods/5070774
A11: 추천 | B11: 가성비 소포장 과자(브랜드 무관) | C11: [오리온] 초코칩쿠키 256g | D11: 3070 | E11: 2 | F11: =D11*E11 -> 6140 | G11: 0 | H11: 999 | I11: https://www.kurly.com/goods/1000640850
A12: 추천 | B12: 가성비 소포장 과자(브랜드 무관) | C12: [롯데] 롯데샌드 파인애플 315g | D12: 4080 | E12: 2 | F12: =D12*E12 -> 8160 | G12: 0 | H12: 999 | I12: https://www.kurly.com/goods/5079334
A13: 추천 | B13: 가성비 소포장 과자(브랜드 무관) | C13: [크라운] 고소한 땅콩샌드 279g | D13: 3480 | E13: 2 | F13: =D13*E13 -> 6960 | G13: 0 | H13: 889 | I13: https://www.kurly.com/goods/1000958603
A14: 추천 | B14: 가성비 소포장 과자(브랜드 무관) | C14: [롯데] 빠다코코낫 300g | D14: 4080 | E14: 1 | F14: =D14*E14 -> 4080 | G14: 0 | H14: 999 | I14: https://www.kurly.com/goods/5079335
A15: 추천 | B15: 가성비 소포장 과자(브랜드 무관) | C15: [롯데] 제크 오리지널 300g | D15: 4080 | E15: 1 | F15: =D15*E15 -> 4080 | G15: 0 | H15: 999 | I15: https://www.kurly.com/goods/5079336
A16: 추천 | B16: 가성비 소포장 과자(브랜드 무관) | C16: [크라운] 딸기산도 161g | D16: 2480 | E16: 1 | F16: =D16*E16 -> 2480 | G16: 0 | H16: 999 | I16: https://www.kurly.com/goods/5081479
... A48: 추천 | B48: 파이/케이크(개별포장) | C48: [해태] 오예스 360g 2종 (택1) | D48: 5280 | E48: 2 | F48: =D48*E48 -> 10560 | G48: 0 | H48: 999 | I48: https://www.kurly.com/goods/1000201444

Sheet 카테고리요약
A1: 카테고리 | B1: 품목수 | C1: 금액(원) | D1: 비중
A2: 필수 | B2: =COUNTIF(구매목록!B5:B48,A2) -> 2 | C2: =SUMIF(구매목록!B5:B48,A2,구매목록!F5:F48) -> 104700 | D2: =C2/SUM($C$2:$C$8) -> 0.21009584
A3: 파이/케이크(개별포장) | B3: =COUNTIF(구매목록!B5:B48,A3) -> 7 | C3: =SUMIF(구매목록!B5:B48,A3,구매목록!F5:F48) -> 69864 | D3: =C3/SUM($C$2:$C$8) -> 0.14019232
A4: 쿠키/비스킷(개별포장) | B4: =COUNTIF(구매목록!B5:B48,A4) -> 10 | C4: =SUMIF(구매목록!B5:B48,A4,구매목록!F5:F48) -> 91620 | D4: =C4/SUM($C$2:$C$8) -> 0.18384891
A5: 초콜릿/캔디/젤리 | B5: =COUNTIF(구매목록!B5:B48,A5) -> 6 | C5: =SUMIF(구매목록!B5:B48,A5,구매목록!F5:F48) -> 91920 | D5: =C5/SUM($C$2:$C$8) -> 0.1844509
A6: 가성비 소포장 과자(브랜드 무관) | B6: =COUNTIF(구매목록!B5:B48,A6) -> 12 | C6: =SUMIF(구매목록!B5:B48,A6,구매목록!F5:F48) -> 70100 | D6: =C6/SUM($C$2:$C$8) -> 0.14066589
A7: 개별포장 스낵/감자칩 | B7: =COUNTIF(구매목록!B5:B48,A7) -> 5 | C7: =SUMIF(구매목록!B5:B48,A7,구매목록!F5:F48) -> 57060 | D7: =C7/SUM($C$2:$C$8) -> 0.11449922
A8: 에너지바 | B8: =COUNTIF(구매목록!B5:B48,A8) -> 2 | C8: =SUMIF(구매목록!B5:B48,A8,구매목록!F5:F48) -> 13080 | D8: =C8/SUM($C$2:$C$8) -> 0.02624693

Sheet 후보전체
A1: 상품번호 | B1: 상품명 | C1: 가격 | D1: 정가 | E1: 할인율 | F1: 후기수 | G1: 품절 | H1: 검색어 | I1: 링크
A2: 1002110052 | B2: [마요라] 아페티토 스틱 스낵 2종, 택1 | C2: 8900 | D2: 8900 | E2: 0 | F2: 60 | H2: 가성비 과자 | I2: https://www.kurly.com/goods/1002110052
A3: 1000747182 | B3: [해태] 아이비 309g | C3: 3680 | D3: 3680 | E3: 0 | F3: 999 | H3: 가성비 과자 | I3: https://www.kurly.com/goods/1000747182
A4: 1000343575 | B4: [해태] 자가비 소포장 2종 (택1) | C4: 3580 | D4: 3580 | E4: 0 | F4: 999 | H4: 가성비 과자 | I4: https://www.kurly.com/goods/1000343575
A5: 1000862247 | B5: 대만 누가크래커 대용량 32개입 448g | C5: 13400 | D5: 13400 | E5: 0 | F5: 875 | H5: 가성비 과자 | I5: https://www.kurly.com/goods/1000862247
A6: 1000178183 | B6: [비타비고] 이탈리안 브레드 스틱 4종 (택1) | C6: 4500 | D6: 4500 | E6: 0 | F6: 999 | H6: 가성비 과자 | I6: https://www.kurly.com/goods/1000178183
A7: 5031072 | B7: [밤부] 누가 크래커 140g | C7: 5980 | D7: 5980 | E7: 0 | F7: 999 | H7: 가성비 과자 | I7: https://www.kurly.com/goods/5031072
A8: 1000875821 | B8: [무직타이거] 옛날과자 골라담기 5종 (택1) | C8: 1690 | D8: 1690 | E8: 0 | F8: 999 | H8: 가성비 과자 | I8: https://www.kurly.com/goods/1000875821
A9: 1000651310 | B9: [포테이토 크리스프] 감자칩 2종 (택1) | C9: 7490 | D9: 7490 | E9: 0 | F9: 793 | H9: 가성비 과자 | I9: https://www.kurly.com/goods/1000651310
A10: 1000321598 | B10: [리츠] 크래커 3종 (택1) | C10: 1790 | D10: 2000 | E10: 10 | F10: 999 | H10: 가성비 과자 | I10: https://www.kurly.com/goods/1000321598
A11: 5077465 | B11: [해태] 에이스 364g (24g x 15봉지) | C11: 3980 | D11: 3980 | E11: 0 | F11: 999 | H11: 가성비 과자 | I11: https://www.kurly.com/goods/5077465
A12: 5079319 | B12: [롯데] 꼬깔콘 스낵(소) 4번들 | C12: 3580 | D12: 3580 | E12: 0 | F12: 999 | H12: 가성비 과자 | I12: https://www.kurly.com/goods/5079319
A13: 1000198076 | B13: [해태] 사브레 252g | C13: 3580 | D13: 3580 | E13: 0 | F13: 999 | H13: 가성비 과자 | I13: https://www.kurly.com/goods/1000198076
... A196: 1002129012 | B196: [농심] 감자깡 75g | C196: 1440 | D196: 1440 | E196: 0 | F196: 389 | H196: 감자 스낵 | I196: https://www.kurly.com/goods/1002129012
A197: 1001421090 | B197: [가루비] CALBEE 일본 감자칩 스낵 6종 | C197: 4000 | D197: 4680 | E197: 14 | H197: 감자 스낵 | I197: https://www.kurly.com/goods/1001421090
A198: 1001170989 | B198: [오리온] 눈을감자 칠리치즈프라이즈 96g | C198: 2720 | D198: 2720 | E198: 0 | F198: 494 | H198: 감자 스낵 | I198: https://www.kurly.com/goods/1001170989
A199: 5134076 | B199: [농심] 감자깡 250g (지퍼백) | C199: 4540 | D199: 4540 | E199: 0 | F199: 999 | H199: 감자 스낵 | I199: https://www.kurly.com/goods/5134076
A200: 1000640848 | B200: [오리온] 눈을감자 96g | C200: 2720 | D200: 2720 | E200: 0 | F200: 953 | H200: 감자 스낵 | I200: https://www.kurly.com/goods/1000640848
A201: 1001318650 | B201: [가루비] 쟈가리코 감자 스낵 샐러드맛 57g x 12개입 (가루비 쟈가리코 샐러드맛 57g 12개입) | C201: 28670 | D201: 32500 | E201: 11 | F201: 22 | H201: 감자 스낵 | I201: https://www.kurly.com/goods/1001318650
A202: 1001937064 | B202: [풀무원] 특등급 국산콩 두부칩 감자 40g | C202: 2480 | D202: 2980 | E202: 16 | F202: 534 | H202: 감자 스낵 | I202: https://www.kurly.com/goods/1001937064
A203: 1000612631 | B203: [러플스] 오리지날 감자칩 184.2g | C203: 6490 | D203: 6490 | E203: 0 | F203: 168 | H203: 감자 스낵 | I203: https://www.kurly.com/goods/1000612631
A204: 1000891279 | B204: [올가] 순감자칩, 순고구마칩 2종 (택1) | C204: 3900 | D204: 3900 | E204: 0 | F204: 999 | H204: 감자 스낵 | I204: https://www.kurly.com/goods/1000891279
A205: 1002380802 | B205: [푸르나이] 제대로 햇감자칩 2종, 택1 | C205: 2800 | D205: 2800 | E205: 0 | F205: 240 | H205: 감자 스낵 | I205: https://www.kurly.com/goods/1002380802
A206: 1000584460 | B206: [케오스] 아이리시 씨솔트 크링클 감자칩 125g | C206: 5584 | D206: 6980 | E206: 20 | F206: 347 | H206: 감자 스낵 | I206: https://www.kurly.com/goods/1000584460
A207: 1000179453 | B207: [아로마트러플] 블랙 써머 트러플 감자칩 3종 (택1) | C207: 13900 | D207: 13900 | E207: 0 | F207: 999 | H207: 감자 스낵 | I207: https://www.kurly.com/goods/1000179453
A208: 1000570013 | B208: [켈로그] 프링글스 치즈맛 110g | C208: 3500 | D208: 3500 | E208: 0 | F208: 404 | H208: 감자 스낵 | I208: https://www.kurly.com/goods/1000570013
A209: 1002247128 | B209: [크라운] 어썸체다치즈 45g | C209: 1380 | D209: 1480 | E209: 6 | F209: 292 | H209: 감자 스낵 | I209: https://www.kurly.com/goods/1002247128
... A361: 5086557 | B361: [롯데] 크런키 팔각 빼빼로 140g | C361: 5900 | D361: 5900 | E361: 0 | F361: 999 | H361: 개별포장 쿠키 | I361: https://www.kurly.com/goods/5086557
A362: 1002378498 | B362: [워커스] 쇼트브레드 하이랜더스 200g | C362: 8980 | D362: 8980 | E362: 0 | H362: 개별포장 쿠키 | I362: https://www.kurly.com/goods/1002378498
A363: 1000169834 | B363: [롯데] 엄마손파이 254g | C363: 5380 | D363: 5380 | E363: 0 | F363: 860 | H363: 개별포장 쿠키 | I363: https://www.kurly.com/goods/1000169834
A364: 1000339567 | B364: [롯데] 꼬깔콘 2종 (지퍼백) | C364: 4580 | D364: 4580 | E364: 0 | F364: 967 | H364: 개별포장 쿠키 | I364: https://www.kurly.com/goods/1000339567
A365: 1002378489 | B365: [워커스] 쇼트브레드 라운드 99g (9입) | C365: 6480 | D365: 6480 | E365: 0 | H365: 개별포장 쿠키 | I365: https://www.kurly.com/goods/1002378489
A366: 1000499587 | B366: [마츠나가] 시루코 팥 앙금 샌드 150g | C366: 4980 | D366: 4980 | E366: 0 | F366: 303 | H366: 개별포장 쿠키 | I366: https://www.kurly.com/goods/1000499587
A367: 1002096110 | B367: [롯데] 빼빼로 딸기 37g | C367: 1700 | D367: 1700 | E367: 0 | F367: 141 | H367: 개별포장 쿠키 | I367: https://www.kurly.com/goods/1002096110
A368: 1000909929 | B368: 에어프라이어로 더 맛있어지는 간식 모음 5종 (택1) | C368: 2380 | D368: 2380 | E368: 0 | F368: 9999 | H368: 개별포장 쿠키 | I368: https://www.kurly.com/goods/1000909929
A369: 1002110078 | B369: [해태] 에이스 씬 솔티카라멜 291g | C369: 3980 | D369: 3980 | E369: 0 | F369: 314 | H369: 개별포장 쿠키 | I369: https://www.kurly.com/goods/1002110078
A370: 1001212342 | B370: [해태] 종합 간식 기획팩 (11개입) | C370: 17900 | D370: 17900 | E370: 0 | F370: 162 | H370: 개별포장 쿠키 | I370: https://www.kurly.com/goods/1001212342
A371: 1000339540 | B371: [롯데] 미니 크런키 171g | C371: 6800 | D371: 6800 | E371: 0 | F371: 879 | H371: 개별포장 쿠키 | I371: https://www.kurly.com/goods/1000339540
A372: 1002099578 | B372: [일본디저트여행] 토끼 시로짱 사브레 (25g X 7개) | C372: 11900 | D372: 11900 | E372: 0 | F372: 19 | H372: 개별포장 쿠키 | I372: https://www.kurly.com/goods/1002099578
A373: 1002083404 | B373: [바이런베이] 쿠키 바이츠 5종, 택1 | C373: 5925 | D373: 7900 | E373: 25 | F373: 55 | H373: 개별포장 쿠키 | I373: https://www.kurly.com/goods/1002083404
...
